<?xml version="1.0" ?>
<sdf version="1.5">
	<model name="My_Agent">
	<pose> 0 0 0.05 0 0 0</pose>
	<link name="chassis">
		<collision name="chassis_collision">
		<geometry>
			<box>
				<size>0.07 0.1 0.025</size>
			</box>
		</geometry>
		</collision>
		
		<visual name="chassis_visual">
		<geometry>
			<box>
				<size>0.07 0.1 0.025</size>
			</box>
		</geometry>
		</visual>	
	</link>

	<static> false </static>
	
	<link name="front_right_wheel">
        <pose> 0.045 0.045 0 0 1.5707 0 </pose>
        <collision name="collision">
          <geometry>
            <cylinder>
              <radius>.03</radius>
              <length>.015</length>
            </cylinder>
          </geometry>
        </collision>
        <visual name="visual">
          <geometry>
            <cylinder>
              <radius>.03</radius>
              <length>.015</length>
            </cylinder>
          </geometry>
        </visual>
    </link>
	
	<link name="front_left_wheel">
        <pose> -0.045 0.045 0 0 1.5707 0 </pose>
        <collision name="collision">
          <geometry>
            <cylinder>
              <radius>.03</radius>
              <length>.015</length>
            </cylinder>
          </geometry>
        </collision>
        <visual name="visual">
          <geometry>
            <cylinder>
              <radius>.03</radius>
              <length>.015</length>
            </cylinder>
          </geometry>
        </visual>
    </link>
  
	<link name="rear_right_wheel">
        <pose> 0.045 -0.045 0 0 1.5707 0 </pose>
        <collision name="collision">
          <geometry>
            <cylinder>
              <radius>.03</radius>
              <length>.015</length>
            </cylinder>
          </geometry>
        </collision>
        <visual name="visual">
          <geometry>
            <cylinder>
              <radius>.03</radius>
              <length>.015</length>
            </cylinder>
          </geometry>
        </visual>
	</link>
	
	<link name="rear_left_wheel">
        <pose> -0.045 -0.045 0 0 1.5707 0 </pose>
        <collision name="collision">
          <geometry>
            <cylinder>
              <radius>.03</radius>
              <length>.015</length>
            </cylinder>
          </geometry>
        </collision>
        <visual name="visual">
          <geometry>
            <cylinder>
              <radius>.03</radius>
              <length>.015</length>
            </cylinder>
          </geometry>
        </visual>
    </link>
	
	<!-- Motion Joints -->
	<joint type="revolute" name="front_right_wheel_hinge">
        <pose>0 0 -0.0175 0 0 0</pose>
        <child>front_right_wheel</child>
        <parent>chassis</parent>
        <axis>
          <xyz>0 0 1</xyz>
        </axis>
	</joint>
	
	<joint type="revolute" name="front_left_wheel_hinge">
        <pose>0 0 0.0175 0 0 0</pose>
        <child>front_left_wheel</child>
        <parent>chassis</parent>
        <axis>
          <xyz>0 0 1</xyz>
        </axis>
	</joint>
	
	<joint type="revolute" name="rear_right_wheel_hinge">
        <pose>0 0 -0.0175 0 0 0</pose>
        <child>rear_right_wheel</child>
        <parent>chassis</parent>
        <axis>
          <xyz>0 0 1</xyz>
        </axis>
	</joint>

	<joint type="revolute" name="rear_left_wheel_hinge">
        <pose>0 0 0.0175 0 0 0</pose>
        <child>rear_left_wheel</child>
        <parent>chassis</parent>
        <axis>
          <xyz>0 0 1</xyz>
        </axis>
	</joint>
	
	<!-- Make base for Lidar sensor -->
	<link name="Lidar_Base">
		<pose> 0 0 0.02125 0 0 0 </pose>
		<collision name="Lidar Base collision">
			<geometry>
				<box>
					<size> 0.04 0.04 0.0175 </size>
				</box>
			</geometry>
		</collision>
		<visual name="Lidar_base_visual">
			<geometry>
				<box>
					<size> 0.04 0.04 0.0175 </size>
				</box>
			</geometry>
		</visual>
	</link>
	
	<joint name="Lidar_Base_Joint" type="fixed">
		<pose> 0 0 -0.02 0 0 0 </pose>
		<child> Lidar_Base </child>
		<parent> chassis </parent>
	</joint>

	<!-- Add Lidar sensor -->
	<include>
		<uri> model://MyLidar </uri>
		<pose> 0 0 0.015 0 0 0</pose>
	</include>

	<joint name="lidar_joint" type="fixed">
		<pose> 0 0 -0.015 0 0 0 </pose>
		<child>My_Lidar::body</child>
		<parent>Lidar_Base</parent>
	</joint>

	</model>
</sdf>
