<?xml version="1.0" ?>
<sdf version="1.5">
	<model name="My_Agent">
	<pose> 0 0 0.05 0 0 0</pose>
	<link name="body">
		<collision name="body_collision">
		<geometry>
			<box>
				<size>0.07 0.1 0.025</size>
			</box>
		</geometry>
		</collision>
		
		<inertial>
        <mass>0.2</mass>
        <inertia>
          <ixx>0.005</ixx>
          <ixy>0.0</ixy>
          <ixz>0.0</ixz>
          <iyy>0.005</iyy>
          <iyz>0.0</iyz>
          <izz>0.005</izz>
        </inertia>
		</inertial>

		<visual name="body_visual">
		<geometry>
			<box>
				<size>0.07 0.1 0.025</size>
			</box>
		</geometry>
		</visual>	
	</link>

    <link name="rear_right_wheel_link">
      <pose frame="">-0.035 0.05 0 0 0 0</pose>
      <inertial>
        <pose frame="">-0.005 0 0 0 -0 0</pose>
        <mass>0.2</mass>
        <inertia>
          <ixx>0.02467</ixx>
          <ixy>0</ixy>
          <ixz>0</ixz>
          <iyy>0.04411</iyy>
          <iyz>0</iyz>
          <izz>0.02467</izz>
        </inertia>
      </inertial>
      <collision name="rear_right_wheel_link_collision">
        <pose frame="">-0.005 0 0 0 1.570796 0</pose>
        <geometry>
          <cylinder>
            <length>0.01</length>
            <radius>0.02</radius>
          </cylinder>
        </geometry>
        <surface>
          <contact>
            <ode>
              <kp>1e+07</kp>
              <kd>1</kd>
            </ode>
          </contact>
          <friction>
            <ode>
              <mu>0.5</mu>
              <mu2>1</mu2>
              <slip1>0.00062</slip1>
              <slip2>0</slip2>
              <fdir1>0 0 1</fdir1>
            </ode>
          </friction>
        </surface>
      </collision>
      <visual name="rear_right_wheel_link_visual">
        <pose frame="">-0.005 0 0 0 1.570796 0</pose>
        <geometry>
          <cylinder>
            <length>0.01</length>
            <radius>0.02</radius>
          </cylinder>
        </geometry>
      </visual>
      <gravity>1</gravity>
      <velocity_decay/>
    </link>
    <joint name="rear_right_wheel_joint" type="revolute">
      <child>rear_right_wheel_link</child>
      <parent>body</parent>
      <axis>
        <xyz>0 1 0</xyz>
        <limit>
          <lower>-1e+16</lower>
          <upper>1e+16</upper>
        </limit>
        <dynamics>
          <spring_reference>0</spring_reference>
          <spring_stiffness>0</spring_stiffness>
        </dynamics>
        <use_parent_model_frame>1</use_parent_model_frame>
      </axis>
    </joint> 

    <link name="rear_left_wheel_link">
      <pose frame="">0.035 0.05 0 0 0 0</pose>
      <inertial>
        <pose frame="">0.005 0 0 0 -0 0</pose>
        <mass>0.2</mass>
        <inertia>
          <ixx>0.02467</ixx>
          <ixy>0</ixy>
          <ixz>0</ixz>
          <iyy>0.04411</iyy>
          <iyz>0</iyz>
          <izz>0.02467</izz>
        </inertia>
      </inertial>
      <collision name="rear_left_wheel_link_collision">
        <pose frame="">0.005 0 0 0 1.570796 0</pose>
        <geometry>
          <cylinder>
            <length>0.01</length>
            <radius>0.02</radius>
          </cylinder>
        </geometry>
        <surface>
          <contact>
            <ode>
              <kp>1e+07</kp>
              <kd>1</kd>
            </ode>
          </contact>
          <friction>
            <ode>
              <mu>0.5</mu>
              <mu2>1</mu2>
              <slip1>0.00062</slip1>
              <slip2>0</slip2>
              <fdir1>0 0 1</fdir1>
            </ode>
          </friction>
        </surface>
      </collision>
      <visual name="rear_left_wheel_link_visual">
        <pose frame="">0.005 0 0 0 1.570796 0</pose>
        <geometry>
          <cylinder>
            <length>0.01</length>
            <radius>0.02</radius>
          </cylinder>
        </geometry>
      </visual>
      <gravity>1</gravity>
      <velocity_decay/>
    </link>
    <joint name="rear_left_wheel_joint" type="revolute">
      <child>rear_left_wheel_link</child>
      <parent>body</parent>
      <axis>
        <xyz>0 1 0</xyz>
        <limit>
          <lower>-1e+16</lower>
          <upper>1e+16</upper>
        </limit>
        <dynamics>
          <spring_reference>0</spring_reference>
          <spring_stiffness>0</spring_stiffness>
        </dynamics>
        <use_parent_model_frame>1</use_parent_model_frame>
      </axis>
    </joint> 

    <link name="front_right_wheel_link">
      <pose frame="">-0.035 -0.05 0 0 0 0</pose>
      <inertial>
        <pose frame="">0.005 0 0 0 -0 0</pose>
        <mass>0.2</mass>
        <inertia>
          <ixx>0.02467</ixx>
          <ixy>0</ixy>
          <ixz>0</ixz>
          <iyy>0.04411</iyy>
          <iyz>0</iyz>
          <izz>0.02467</izz>
        </inertia>
      </inertial>
      <collision name="front_right_wheel_link_collision">
        <pose frame="">-0.005 0 0 0 1.570796 0</pose>
        <geometry>
          <cylinder>
            <length>0.01</length>
            <radius>0.02</radius>
          </cylinder>
        </geometry>
        <surface>
          <contact>
            <ode>
              <kp>1e+07</kp>
              <kd>1</kd>
            </ode>
          </contact>
          <friction>
            <ode>
              <mu>0.5</mu>
              <mu2>1</mu2>
              <slip1>0.00062</slip1>
              <slip2>0</slip2>
              <fdir1>0 0 1</fdir1>
            </ode>
          </friction>
        </surface>
      </collision>
      <visual name="front_right_wheel_link_visual">
        <pose frame="">-0.005 0 0 0 1.570796 0</pose>
        <geometry>
          <cylinder>
            <length>0.01</length>
            <radius>0.02</radius>
          </cylinder>
        </geometry>
      </visual>
      <gravity>1</gravity>
      <velocity_decay/>
    </link>
    <joint name="front_right_wheel_joint" type="revolute">
      <child>front_right_wheel_link</child>
      <parent>body</parent>
      <axis>
        <xyz>0 1 0</xyz>
        <limit>
          <lower>-1e+16</lower>
          <upper>1e+16</upper>
        </limit>
        <dynamics>
          <spring_reference>0</spring_reference>
          <spring_stiffness>0</spring_stiffness>
        </dynamics>
        <use_parent_model_frame>1</use_parent_model_frame>
      </axis>
    </joint> 

    <link name="front_left_wheel_link">
      <pose frame="">0.035 -0.05 0 0 0 0</pose>
      <inertial>
        <pose frame="">0.005 0 0 0 -0 0</pose>
        <mass>0.2</mass>
        <inertia>
          <ixx>0.02467</ixx>
          <ixy>0</ixy>
          <ixz>0</ixz>
          <iyy>0.04411</iyy>
          <iyz>0</iyz>
          <izz>0.02467</izz>
        </inertia>
      </inertial>
      <collision name="front_left_wheel_link_collision">
        <pose frame="">0.005 0 0 0 1.570796 0</pose>
        <geometry>
          <cylinder>
            <length>0.01</length>
            <radius>0.02</radius>
          </cylinder>
        </geometry>
        <surface>
          <contact>
            <ode>
              <kp>1e+07</kp>
              <kd>1</kd>
            </ode>
          </contact>
          <friction>
            <ode>
              <mu>0.5</mu>
              <mu2>1</mu2>
              <slip1>0.00062</slip1>
              <slip2>0</slip2>
              <fdir1>0 0 1</fdir1>
            </ode>
          </friction>
        </surface>
      </collision>
      <visual name="front_left_wheel_link_visual">
        <pose frame="">0.005 0 0 0 1.570796 0</pose>
        <geometry>
          <cylinder>
            <length>0.01</length>
            <radius>0.02</radius>
          </cylinder>
        </geometry>
      </visual>
      <gravity>1</gravity>
      <velocity_decay/>
    </link>
    <joint name="front_left_wheel_joint" type="revolute">
      <child>front_left_wheel_link</child>
      <parent>body</parent>
      <axis>
        <xyz>0 1 0</xyz>
        <limit>
          <lower>-1e+16</lower>
          <upper>1e+16</upper>
        </limit>
        <dynamics>
          <spring_reference>0</spring_reference>
          <spring_stiffness>0</spring_stiffness>
        </dynamics>
        <use_parent_model_frame>1</use_parent_model_frame>
      </axis>
    </joint> 

	</model>
</sdf>
